Workbook

Sheet Guia
A1: ALCOPALET (DTI-1399) — Modelo de análisis
A2: Trabajo final del Programa LYDES 2026 · Instituto Internacional San Telmo
A4: CÓMO USAR ESTE LIBRO
A5: Regla general | B5: Ninguna cifra de resultado está escrita a mano: todas son fórmulas. Al cambiar una hipótesis, el libro entero se recalcula.
A6: Dónde tocar | B6: Solo en la hoja «Datos». El bloque H reúne las hipótesis propias, que son las que hay que declarar y defender ante el jurado.
A7: Azul | B7: Dato tomado literalmente del enunciado o de sus anexos.
A8: Negro | B8: Resultado calculado en la propia hoja.
A9: Verde | B9: Enlace a otra hoja del libro.
A10: Relleno amarillo | B10: Hipótesis del analista, NO dada por el caso. Hay que justificarla.
A12: CONTENIDO DE LAS HOJAS
A13: Datos | B13: Todos los datos del enunciado y los tres anexos, más las hipótesis propias.
A14: PyG2025 | B14: Anexo 1 recalculado, con contraste contra el valor publicado y conversión del EBITDA en caja.
A15: Lineas | B15: Anexo 2 y comprobación de que las dos líneas suman el consolidado.
A16: Escandallo | B16: Anexo 3 con el coste y el margen recalculados, y reconciliación completa contra la cuenta de resultados.
A17: Capacidad | B17: Capacidad anual de cada sistema, grado de utilización y encaje de Persán en la fábrica. El caso no da estos datos hechos.
A18: Persan | B18: Cuenta de resultados incremental del contrato, circulante, precio de equilibrio, riesgo del precio de la madera y escenario renegociado.
A19: Robot | B19: La máquina analizada por separado del contrato: comparativa técnica, ahorro de mano de obra, efecto de la restricción «sin despidos» y coste de oportunidad.
A20: Escenarios | B20: Las cinco opciones comparadas en resultado, caja y criterios cualitativos.
A21: Sensibilidad | B21: Tabla de doble entrada precio × precio de la madera, y sensibilidad al plazo de cobro.
A23: LOS CINCO NÚMEROS QUE SOSTIENEN EL ANÁLISIS
A24: Margen unitario Persán | B24: =Escandallo!$D$11 -> -0.52 | C24: Negativo. Está en el propio Anexo 3 del caso: el contrato no cubre ni los costes variables.
A25: Impacto anual del contrato | B25: =Persan!$B$19 -> -188876.67 | C25: Con campa, leasing y coste del circulante incluidos.
A26: Precio de equilibrio | B26: =Persan!$B$28 -> 12.170128 | C26: Por debajo de este precio el contrato destruye valor, con o sin máquina.
A27: Capacidad anual actual (palets) | B27: =Capacidad!$D$8 -> 215380 | C27: Frente a 174.504 palets producidos en 2025: la fábrica está al 81%, no llena.
A28: Caja operativa real de 2025 | B28: =PyG2025!$B$31 -> -60555 | C28: Frente a 279.364 € de beneficio contable. El beneficio no es caja repartible.
A30: ADVERTENCIAS DE HONESTIDAD ANALÍTICA
A31: • | B31: El coste del circulante es una aproximación de bolsillo (saldo medio × tipo de interés), no un estado de tesorería completo. Sirve como orden de magnitud.
A32: • | B32: El caso no dice si existe demanda suficiente para llenar la capacidad del robot a precio de mercado. Hoy la fábrica está al 81%, así que la demanda es hoy la restricción real.
A33: • | B33: El importe de la casa que quieren comprar los fundadores no aparece en el caso. La cifra usada es una hipótesis de trabajo, señalada en amarillo.
A34: • | B34: La mano de obra directa del escandallo (646.000 €) no cuadra con la partida de personal de producción del Anexo 1 (481.660 €). El escandallo sí cuadra con la plantilla real (17 operarios × 38.000 €), por lo que se ha tomado como base.
A35: • | B35: El anexo publica un coste manual de 12,36 €; la suma exacta de sus componentes da 12,37 €. Diferencia de redondeo, sin efecto en las conclusiones.

Sheet Datos
A1: ALCOPALET (DTI-1399) — Datos e hipótesis del caso
A2: Programa Lydes 2026. Azul = dato del enunciado · Negro = fórmula · Amarillo = hipótesis propia del analista (no dada por el caso).
A4: A. PARÁMETROS GENERALES DE CÁLCULO
A5: Meses productivos al año | B5: 11 | C5: Nota final del Anexo 3 del caso.
A6: Días productivos al mes | B6: 22 | C6: Nota final del Anexo 3 del caso.
A7: Días productivos al año | B7: =Datos!$B$5*Datos!$B$6 -> 242 | C7: Calculado: 11 × 22 = 242 días.
A8: Horas por jornada | B8: 8 | C8: Turno único de 7:00 a 15:00. Esteban descarta turnos de tarde y noche.
A9: Coste medio de mano de obra (€/año) | B9: 38000 | C9: Sueldos y cotizaciones sociales. Apartado (d) del caso.
A10: Coste medio de despido (€/trabajador) | B10: 30000 | C10: Elevado por la antigüedad de la plantilla. Apartado (d) del caso.
A11: Tipo de interés de la financiación | B11: 0.075 | C11: Ofrecido por la entidad financiera habitual. Apartado (c) del caso.
A13: B. CONTRATO PERSÁN
A14: Volumen anual comprometido (palets) | B14: 90000 | C14: 90 mil unidades/año.
A15: Precio de venta unitario (€) | B15: 10 | C15: PVunit = 10 € FIJO durante los 5 años. Sin cláusula de revisión.
A16: Duración del contrato (años) | B16: 5
A17: Plazo de cobro (días) | B17: 180 | C17: Pago a 180 días.
A18: Retén permanente exigido (palets) | B18: 1000 | C18: Dos camiones en nave para garantizar servicio en menos de 24 horas.
A20: C. LÍNEA AUTOMÁTICA (instalada en 2019)
A21: Capacidad nominal (palets/hora) | B21: 65
A22: Rendimiento considerado | B22: 0.75 | C22: Alcopalet la considera al 75% por su mantenimiento complejo y constante.
A23: Operarios necesarios | B23: 2
A24: Coste de adquisición (€) | B24: 360000 | C24: Nota ** del Anexo 1.
A25: Periodo de amortización (años) | B25: 10
A26: Amortización anual (€) | B26: =Datos!$B$24/Datos!$B$25 -> 36000 | C26: 36.000 € frente a los 36.143 € del Anexo 1: la diferencia son otros inmovilizados menores.
A27: Cambio de formato — mínimo (horas) | B27: 4
A28: Cambio de formato — máximo (horas) | B28: 6 | C28: Parada total de la línea. Es la gran rigidez de esta instalación (38 metros).
A30: D. FABRICACIÓN MANUAL (palet nuevo)
A31: Operarios | B31: 8
A32: Producción total (palets/día) | B32: 500
A33: Productividad (palets/operario/día) | B33: =Datos!$B$32/Datos!$B$31 -> 62.5 | C33: Dato derivado, necesario para valorar la sustitución por el robot.
A35: E. LÍNEA DE PALET USADO (Palet Ojeda)
A36: Operarios | B36: 7
A37: Productividad (palets/persona/día) | B37: 155
A38: Techo logístico (palets/mes) | B38: 30000 | C38: Techo por FALTA DE ESPACIO, no por falta de demanda. Clave del caso.
A39: Techo logístico (palets/año) | B39: =Datos!$B$38*12 -> 360000
A41: F. NUEVO ROBOT PARA PALETS
A42: Inversión (€) | B42: 40000
A43: Producción (palets/jornada) | B43: 400
A44: Rendimiento considerado | B44: 0.9 | C44: Frente al 75% de la línea de 2019: sin electrónica compleja ni rodamientos.
A45: Operarios necesarios | B45: 1 | C45: Un solo operario dedicado en exclusiva a la máquina (nota 1 del Anexo 3).
A46: Cambio de formato (minutos) | B46: 25 | C46: Entre 20 y 30 minutos, frente a 4-6 HORAS de la línea de 2019.
...

Sheet PyG2025
A1: Anexo 1 — Cuenta de pérdidas y ganancias consolidada 2025
A2: Los subtotales se recalculan con fórmulas y se contrastan contra el valor publicado en el anexo (columna de diferencia).
A4: Concepto | B4: Importe 2025 | C4: % s/ Ventas | D4: Valor del anexo | E4: Diferencia | F4: Comentario
A5: VENTAS NETAS | B5: 4585267 | C5: =B5/$B$5 -> 1
A6: Variación de existencias | B6: 376062 | C6: =B6/$B$5 -> 0.082015289 | F6: Aumento de existencias: es beneficio contable, pero NO es caja.
A7: Aprovisionamientos | B7: -3068506 | C7: =B7/$B$5 -> -0.66920988 | F7: Compras del ejercicio. El consumo real es Aprovisionamientos − Variación.
A8: MARGEN BRUTO | B8: =SUM(B5:B7) -> 1892823 | C8: =B8/$B$5 -> 0.4128054 | D8: 1892822 | E8: =B8-D8 -> 1
A9: Gastos de Personal — Producción | B9: -481660 | C9: =B9/$B$5 -> -0.10504514
A10: Gastos de Transporte | B10: -268218 | C10: =B10/$B$5 -> -0.058495612 | F10: Coste total de los 2 camiones actuales, YA al 100% de su capacidad.
A11: Gastos de Personal — Estructura/Admin. | B11: -311292 | C11: =B11/$B$5 -> -0.067889613
A12: Otros Costes de Explotación | B12: -378979 | C12: =B12/$B$5 -> -0.082651457 | F12: El 60% corresponde a la línea de palet nuevo (apartado (e) del caso).
A13: EBITDA | B13: =B8+SUM(B9:B12) -> 452674 | C13: =B13/$B$5 -> 0.098723586 | D13: 452674 | E13: =B13-D13 -> 0
A14: Amortización del Inmovilizado | B14: -36143 | C14: =B14/$B$5 -> -0.0078824199 | F14: Línea de 2019: 360.000 € a 10 años = 36.000 €/año.
A15: RESULTADO DE EXPLOTACIÓN (EBIT) | B15: =B13+B14 -> 416531 | C15: =B15/$B$5 -> 0.090841166 | D15: 416531 | E15: =B15-D15 -> 0
A16: Gastos Financieros | B16: -44046 | C16: =B16/$B$5 -> -0.0096059837
A17: RESULTADO ANTES DE IMPUESTOS | B17: =B15+B16 -> 372485 | C17: =B17/$B$5 -> 0.081235182 | D17: 372485 | E17: =B17-D17 -> 0
A18: Impuestos (estimado) | B18: -93121 | C18: =B18/$B$5 -> -0.020308741
A19: RESULTADO NETO DEL EJERCICIO | B19: =B17+B18 -> 279364 | C19: =B19/$B$5 -> 0.060926441 | D19: 279364 | E19: =B19-D19 -> 0
A21: RATIOS Y LECTURA DE CAJA
A22: Tipo impositivo efectivo | B22: =PyG2025!$B$18/-PyG2025!$B$17 -> 0.24999933 | C22: Coherente con un tipo del 25%.
A23: Margen EBITDA sobre ventas | B23: =PyG2025!$B$13/PyG2025!$B$5 -> 0.098723586
A24: Margen neto sobre ventas | B24: =PyG2025!$B$19/PyG2025!$B$5 -> 0.060926441
A26: Conversión del EBITDA en caja (aproximación)
A27: EBITDA | B27: =PyG2025!$B$13 -> 452674
A28: (−) Aumento de existencias | B28: =-PyG2025!$B$6 -> -376062 | C28: Salida de caja: se ha fabricado y comprado más de lo vendido.
A29: (−) Gastos financieros | B29: =PyG2025!$B$16 -> -44046
A30: (−) Impuestos | B30: =PyG2025!$B$18 -> -93121
A31: CAJA OPERATIVA APROXIMADA 2025 | B31: =B27+B28+B29+B30 -> -60555 | F31: Frente a un beneficio contable de 279.364 €. El beneficio no es caja disponible: el argumento central frente a la petición de dividendo.
A33: Nota: el aumento de existencias puede ser puntual (acopio de madera gallega). Aun así, muestra que 2025 generó mucha menos caja libre de la que sugiere el beneficio.

Sheet Lineas
A1: Anexo 2 — Rentabilidad por líneas de negocio 2025
A2: Comprobación de que las dos líneas suman exactamente el consolidado del Anexo 1.
A4: Concepto | B4: ALCOPALET (Nuevo) | C4: PALET OJEDA (Usado) | D4: TOTAL | E4: Anexo 1 | F4: Diferencia
A5: Ventas netas (€) | B5: 2645224 | C5: 1940042 | D5: =B5+C5 -> 4585266 | E5: =PyG2025!$B$5 -> 4585267 | F5: =D5-E5 -> -1
A6: Resultado neto (€) | B6: 158882 | C6: 120482 | D6: =B6+C6 -> 279364 | E6: =PyG2025!$B$19 -> 279364 | F6: =D6-E6 -> 0
A7: Unidades vendidas (palets) | B7: 174504 | C7: 260330 | D7: =B7+C7 -> 434834
A9: INDICADORES DERIVADOS
A10: Precio medio de venta (€/palet) | B10: =B5/B7 -> 15.158529 | C10: =C5/C7 -> 7.4522414 | F10: Coincide con el ingreso medio del Anexo 3 (15,16 € y 7,45 €): los anexos son coherentes.
A11: Resultado neto por palet (€) | B11: =B6/B7 -> 0.9104777 | C11: =C6/C7 -> 0.4628049
A12: Margen neto sobre ventas | B12: =B6/B5 -> 0.060063722 | C12: =C6/C5 -> 0.062102779
A13: Peso sobre ventas totales | B13: =B5/$D$5 -> 0.57689652 | C13: =C5/$D$5 -> 0.42310348
A14: Peso sobre resultado total | B14: =B6/$D$6 -> 0.56872754 | C14: =C6/$D$6 -> 0.43127246 | F14: El palet usado aporta el 43% del beneficio con el 42% de las ventas.

Sheet Escandallo
A1: Anexo 3 — Escandallo de costes unitarios (€/palet)
A2: El coste y el margen se recalculan sumando los componentes, en lugar de copiar el total del anexo. Así se detecta cualquier redondeo.
A4: Concepto de coste | B4: Manual actual (2025) | C4: Palet usado (2025) | D4: Proyecto Persán | F4: Notas del anexo
A5: Ingreso (medio) | B5: 15.16 | C5: 7.45 | D5: 10 | F5: El precio Persán está un 34% por debajo del precio medio actual del palet nuevo.
A6: Materia prima (madera y clavos) | B6: 8.27 | C6: 4.8 | D6: 8.27 | F6: IDÉNTICA en manual y Persán: el robot no reduce el coste de la madera.
A7: Mano de obra directa (MOD) | B7: 2.18 | C7: 1.02 | D7: 0.42 | F7: (1) 90.000 ud/año con un solo operario: 38.000 € / 90.000 = 0,42 €.
A8: Gastos de transporte | B8: 0.62 | C8: 0.62 | D8: 0.53 | F8: (2) Considera el nuevo tráiler propio a plena carga en las rutas de Persán.
A9: Otros costes de explotación variables | B9: 1.3 | C9: 0.58 | D9: 1.3 | F9: (3) Varían proporcionalmente al volumen (electricidad, mantenimiento, etc.).
A10: COSTE DE PRODUCCIÓN UNITARIO | B10: =SUM(B6:B9) -> 12.37 | C10: =SUM(C6:C9) -> 7.02 | D10: =SUM(D6:D9) -> 10.52 | F10: El anexo publica 12,36 € en manual; la suma exacta da 12,37 €. Redondeo de 0,01 €, sin efecto material.
A11: MARGEN DE CONTRIBUCIÓN UNITARIO | B11: =B5-B10 -> 2.79 | C11: =C5-C10 -> 0.43 | D11: =D5-D10 -> -0.52 | F11: HALLAZGO CENTRAL: el margen del proyecto Persán es NEGATIVO. Ni siquiera cubre los costes variables.
A12: Margen sobre precio de venta | B12: =B11/B5 -> 0.18403694 | C12: =C11/C5 -> 0.057718121 | D12: =D11/D5 -> -0.052
A13: Peso de la materia prima sobre el precio | B13: =B6/B5 -> 0.54551451 | C13: =C6/C5 -> 0.6442953 | D13: =D6/D5 -> 0.827 | F13: En Persán la madera se come el 83% del precio. Sin cláusula de revisión a 5 años, es el riesgo principal del contrato.
A15: RECONCILIACIÓN DEL ESCANDALLO CON LA CUENTA DE RESULTADOS
A16: Partida | B16: Según escandallo | C16: Según Anexo 1 | D16: Diferencia | E16: % desvío | F16: Lectura
A17: Materia prima (consumo real) | B17: =Escandallo!$B$6*Lineas!$B$7+Escandallo!$C$6*Lineas!$C$7 -> 2692732.1 | C17: =-(PyG2025!$B$7+PyG2025!$B$6) -> 2692444 | D17: =B17-C17 -> 288.08 | E17: =IF(C17=0,0,(B17-C17)/C17) -> 0.00010699573 | F17: Consumo = Aprovisionamientos − Variación de existencias. Cuadra al 0,01%.
A18: Gastos de transporte | B18: =Escandallo!$B$8*Lineas!$B$7+Escandallo!$C$8*Lineas!$C$7 -> 269597.08 | C18: =-PyG2025!$B$10 -> 268218 | D18: =B18-C18 -> 1379.08 | E18: =IF(C18=0,0,(B18-C18)/C18) -> 0.0051416385 | F18: Cuadra.
A19: Otros costes de explotación | B19: =Escandallo!$B$9*Lineas!$B$7+Escandallo!$C$9*Lineas!$C$7 -> 377846.6 | C19: =-PyG2025!$B$12 -> 378979 | D19: =B19-C19 -> -1132.4 | E19: =IF(C19=0,0,(B19-C19)/C19) -> -0.0029880284 | F19: Cuadra.
A20: Mano de obra directa | B20: =Escandallo!$B$7*Lineas!$B$7+Escandallo!$C$7*Lineas!$C$7 -> 645955.32 | C20: =-PyG2025!$B$9 -> 481660 | D20: =B20-C20 -> 164295.32 | E20: =IF(C20=0,0,(B20-C20)/C20) -> 0.34110227 | F20: NO cuadra: el escandallo recoge 17 operarios × 38.000 € = 646.000 €, mientras el Anexo 1 imputa 481.660 € a Producción. Parte de la plantilla directa está clasificada en Estructura. No invalida el escandallo.
A22: Comprobación de plantilla directa implícita en el escandallo
A23: Operarios implícitos — palet nuevo | B23: =Escandallo!$B$7*Lineas!$B$7/Datos!$B$9 -> 10.011019 | F23: Da 10 operarios: los 8 de manual más los 2 de la línea automática. Coherente.
A24: Operarios implícitos — palet usado | B24: =Escandallo!$C$7*Lineas!$C$7/Datos!$B$9 -> 6.9878053 | F24: Da 7 operarios. Coincide exactamente con el dato del caso: el escandallo es fiable.

Sheet Capacidad
A1: Capacidad productiva — el dato que el caso no da hecho
A2: El caso da rendimientos por hora y por jornada, pero nunca la capacidad anual. Sin ella no se puede saber si Persán cabe en la fábrica.
A4: A. CAPACIDAD ACTUAL DE LA LÍNEA DE PALET NUEVO
A5: Recurso | B5: Palets/día | C5: Días/año | D5: Palets/año | E5: Operarios | F5: Cálculo
A6: Línea automática (2019) | B6: =Datos!$B$21*Datos!$B$22*Datos!$B$8 -> 390 | C6: =Datos!$B$7 -> 242 | D6: =B6*C6 -> 94380 | E6: =Datos!$B$23 -> 2 | F6: 65 palets/h × 75% de rendimiento × 8 h de jornada.
A7: Fabricación manual | B7: =Datos!$B$32 -> 500 | C7: =Datos!$B$7 -> 242 | D7: =B7*C7 -> 121000 | E7: =Datos!$B$31 -> 8 | F7: 500 palets/día entre 8 operarios = 62,5 palets por operario y día.
A8: CAPACIDAD ACTUAL TOTAL | B8: =B6+B7 -> 890 | D8: =D6+D7 -> 215380 | E8: =E6+E7 -> 10
A10: B. GRADO DE UTILIZACIÓN ACTUAL
A11: Producción real 2025 (palet nuevo) | B11: =Lineas!$B$7 -> 174504
A12: Capacidad teórica anual | B12: =Capacidad!$D$8 -> 215380
A13: GRADO DE UTILIZACIÓN | B13: =B11/B12 -> 0.8102145 | F13: La fábrica NO está llena: hay recorrido antes de invertir.
A14: Capacidad ociosa disponible hoy | B14: =B12-B11 -> 40876 | F14: Casi 41.000 palets/año que hoy se pueden fabricar sin invertir un euro. Esto debilita el argumento de que la máquina es imprescindible.
A16: C. EL ROBOT Y EL ENCAJE DEL CONTRATO PERSÁN
A17: Robot — producción efectiva (palets/día) | B17: =Datos!$B$43*Datos!$B$44 -> 360 | F17: 400 palets/jornada × 90% de rendimiento.
A18: Robot — capacidad anual (palets) | B18: =B17*Datos!$B$7 -> 87120
A19: Persán — necesidad diaria (palets/día) | B19: =Datos!$B$14/Datos!$B$7 -> 371.90083 | F19: 90.000 / 242 días.
A20: Persán — necesidad anual (palets) | B20: =Datos!$B$14 -> 90000
A21: DÉFICIT/SUPERÁVIT del robot frente a Persán | B21: =B18-B20 -> -2880 | F21: El robot en solitario NO llega a las 90.000 unidades: se queda un 3,2% corto. Habría que completarlo con las otras líneas o con días extra.
A22: Déficit en % del compromiso | B22: =B21/B20 -> -0.032
A24: D. ¿CABE PERSÁN EN LA FÁBRICA? (con y sin robot)
A25: Escenario | B25: Capacidad anual | C25: Demanda anual | D25: Holgura | E25: ¿Encaja? | F25: Lectura
A26: Sin robot, sin Persán | B26: =Capacidad!$D$8 -> 215380 | C26: =Lineas!$B$7 -> 174504 | D26: =B26-C26 -> 40876 | E26: =IF(D26>=0,"SÍ","NO") -> SÍ | F26: Situación actual: sobra capacidad.
A27: Sin robot, CON Persán | B27: =Capacidad!$D$8 -> 215380 | C27: =Lineas!$B$7+Datos!$B$14 -> 264504 | D27: =B27-C27 -> -49124 | E27: =IF(D27>=0,"SÍ","NO") -> NO | F27: NO cabe: faltan unas 49.000 unidades. Hace falta capacidad nueva sí o sí.
A28: Con robot, CON Persán | B28: =Capacidad!$D$8+Capacidad!$B$18 -> 302500 | C28: =Lineas!$B$7+Datos!$B$14 -> 264504 | D28: =B28-C28 -> 37996 | E28: =IF(D28>=0,"SÍ","NO") -> SÍ | F28: Cabe con holgura. Técnicamente el proyecto es viable; el problema es económico.
A29: Con robot, SIN Persán | B29: =Capacidad!$D$8+Capacidad!$B$18 -> 302500 | C29: =Lineas!$B$7 -> 174504 | D29: =B29-C29 -> 127996 | E29: =IF(D29>=0,"SÍ","NO") -> SÍ | F29: Enorme capacidad ociosa: el robot solo tiene sentido si hay demanda que lo llene.
A31: E. LÍNEA DE PALET USADO: CRECIMIENTO BLOQUEADO POR ESPACIO
A32: Producción actual (palets/año) | B32: =Lineas!$C$7 -> 260330
A33: Producción actual (palets/mes) | B33: =B32/12 -> 21694.167
A34: Techo logístico (palets/año) | B34: =Datos!$B$39 -> 360000 | F34: 30.000 unidades/mes. El límite es el ESPACIO, no la demanda.
A35: Recorrido disponible (palets/año) | B35: =B34-B32 -> 99670
A36: Contribución del recorrido (€/año) | B36: =B35*Escandallo!$C$11 -> 42858.1 | F36: Con margen de 0,43 €/ud. Por sí solo no paga la campa de 60.000 €/año, pero sí reparte su coste con una línea que SÍ gana dinero.
A37: Operarios necesarios para alcanzar el techo | B37: =Datos!$B$39/(Datos!$B$7*Datos!$B$37) -> 9.5974407
A38: Operarios adicionales frente a los 7 actuales | B38: =B37-Datos!$B$36 -> 2.5974407 | F38: OPORTUNIDAD: el robot libera personal de palet nuevo; esta línea necesita personal y solo le falta espacio. La campa de Persán resolvería ambas cosas.

Sheet Persan
A1: Análisis económico del contrato Persán
A2: 90.000 unidades/año · 10 €/unidad fijo durante 5 años · cobro a 180 días · retén permanente de 1.000 palets.
A4: A. CUENTA DE RESULTADOS INCREMENTAL DEL CONTRATO (año completo)
A5: Ingresos (90.000 ud × 10 €) | B5: =Datos!$B$14*Datos!$B$15 -> 900000
A6: Costes variables (90.000 ud × 10,52 €) | B6: =-Datos!$B$14*Escandallo!$D$10 -> -946800
A7: MARGEN DE CONTRIBUCIÓN | B7: =B5+B6 -> -46800 | F7: Negativo ANTES de cualquier coste fijo. Ningún volumen arregla esto.
A8: Alquiler de la campa | B8: =-Datos!$B$50 -> -60000 | F8: 5.000 €/mes.
A9: Leasing de máquina + camión | B9: =-Datos!$B$53 -> -48000 | F9: 4.000 €/mes.
A10: RESULTADO ANTES DE COSTE DE CIRCULANTE | B10: =B7+B8+B9 -> -154800
A12: B. NECESIDADES DE CIRCULANTE (el coste oculto del pago a 180 días)
A13: Cuenta a cobrar media (€) | B13: =Datos!$B$14*Datos!$B$15*Datos!$B$17/365 -> 443835.62 | F13: Ingresos × 180/365. Dinero de Alcopalet en manos de Persán de forma permanente.
A14: Retén permanente de 1.000 palets, a coste (€) | B14: =Datos!$B$18*Escandallo!$D$10 -> 10520 | F14: Stock inmovilizado que exige el cliente para servir en menos de 24 horas.
A15: CIRCULANTE TOTAL INMOVILIZADO (€) | B15: =B13+B14 -> 454355.62
A16: Coste financiero anual del circulante (€) | B16: =-B15*Datos!$B$11 -> -34076.671 | F16: Al 7,5% ofrecido por el banco. Es un coste real, aunque no aparezca en el escandallo.
A18: C. IMPACTO TOTAL DEL CONTRATO
A19: IMPACTO ANUAL TOTAL ESTIMADO | B19: =Persan!$B$10+Persan!$B$16 -> -188876.67 | F19: Margen negativo + campa + leasing + coste del circulante.
A20: En % del resultado neto actual de la empresa | B20: =Persan!$B$19/PyG2025!$B$19 -> -0.67609524 | F20: El contrato se llevaría por delante dos tercios del beneficio de TODA la empresa.
A21: Impacto acumulado a 5 años | B21: =Persan!$B$19*Datos!$B$16 -> -944383.36 | F21: Sin cláusula de revisión de precio, el daño se repite cada año.
A22: Resultado neto de la empresa tras Persán | B22: =PyG2025!$B$19+Persan!$B$19 -> 90487.329 | F22: La empresa entraría en pérdidas o quedaría al borde.
A24: D. PRECIO DE EQUILIBRIO: ¿A CUÁNTO HABRÍA QUE VENDER?
A25: Nivel de cobertura | B25: Precio mínimo (€/ud) | C25: Diferencia vs 10 € | D25: % de subida | F25: Qué cubre
A26: 1. Solo costes variables | B26: =Escandallo!$D$10 -> 10.52 | C26: =B26-Datos!$B$15 -> 0.52 | D26: =B26/Datos!$B$15-1 -> 0.052 | F26: Madera, mano de obra, transporte y otros variables.
A27: 2. + campa y leasing | B27: =Escandallo!$D$10+(Datos!$B$50+Datos!$B$53)/Datos!$B$14 -> 11.72 | C27: =B27-Datos!$B$15 -> 1.72 | D27: =B27/Datos!$B$15-1 -> 0.172 | F27: Añade los costes fijos que el contrato obliga a asumir.
A28: 3. + coste del circulante (equilibrio real) | B28: =(Datos!$B$14*Escandallo!$D$10+Datos!$B$50+Datos!$B$53)/(Datos!$B$14*(1-Datos!$B$17/365*Datos!$B$11)) -> 12.170128 | C28: =B28-Datos!$B$15 -> 2.170128 | D28: =B28/Datos!$B$15-1 -> 0.2170128 | F28: PRECIO DE EQUILIBRIO VERDADERO. Resuelve el precio que hace el resultado igual a cero.
A29: 4. + margen equivalente al negocio actual | B29: =B27+Escandallo!$B$11 -> 14.51 | C29: =B29-Datos!$B$15 -> 4.51 | D29: =B29/Datos!$B$15-1 -> 0.451 | F29: Para que Persán sea tan rentable como el resto del palet nuevo (2,79 €/ud).
A31: E. RIESGO DEL PRECIO DE LA MADERA (83% del precio de venta)
A32: Subida del precio de la madera | B32: Coste unitario (€) | C32: Margen unitario (€) | D32: Impacto anual (€) | F32: Lectura
A33: 0 | B33: =Escandallo!$D$6*(1+A33)+Escandallo!$D$7+Escandallo!$D$8+Escandallo!$D$9 -> 10.52 | C33: =Datos!$B$15-B33 -> -0.52 | D33: =C33*Datos!$B$14-Datos!$B$50-Datos!$B$53+Persan!$B$16 -> -188876.67
A34: 0.05 | B34: =Escandallo!$D$6*(1+A34)+Escandallo!$D$7+Escandallo!$D$8+Escandallo!$D$9 -> 10.9335 | C34: =Datos!$B$15-B34 -> -0.9335 | D34: =C34*Datos!$B$14-Datos!$B$50-Datos!$B$53+Persan!$B$16 -> -226091.67
A35: 0.1 | B35: =Escandallo!$D$6*(1+A35)+Escandallo!$D$7+Escandallo!$D$8+Escandallo!$D$9 -> 11.347 | C35: =Datos!$B$15-B35 -> -1.347 | D35: =C35*Datos!$B$14-Datos!$B$50-Datos!$B$53+Persan!$B$16 -> -263306.67
A36: 0.15 | B36: =Escandallo!$D$6*(1+A36)+Escandallo!$D$7+Escandallo!$D$8+Escandallo!$D$9 -> 11.7605 | C36: =Datos!$B$15-B36 -> -1.7605 | D36: =C36*Datos!$B$14-Datos!$B$50-Datos!$B$53+Persan!$B$16 -> -300521.67
A37: 0.2 | B37: =Escandallo!$D$6*(1+A37)+Escandallo!$D$7+Escandallo!$D$8+Escandallo!$D$9 -> 12.174 | C37: =Datos!$B$15-B37 -> -2.174 | D37: =C37*Datos!$B$14-Datos!$B$50-Datos!$B$53+Persan!$B$16 -> -337736.67
A38: El contrato fija el precio de venta durante 5 años pero no fija el precio de la madera. Todo el riesgo de inflación lo asume Alcopalet.
A40: F. ESCENARIO RENEGOCIADO (hipótesis del analista)
A41: Precio renegociado (€/ud) | B41: =Datos!$B$60 -> 12.5 | F41: Editable en la hoja Datos. Comparar siempre con el precio de equilibrio calculado arriba.
A42: Plazo de cobro renegociado (días) | B42: =Datos!$B$61 -> 90
A43: Margen de contribución unitario (€) | B43: =B41-Escandallo!$D$10 -> 1.98
A44: Margen de contribución total (€) | B44: =B43*Datos!$B$14 -> 178200
A45: (−) Campa y leasing | B45: =-Datos!$B$50-Datos!$B$53 -> -108000
A46: (−) Coste del circulante | B46: =-(B41*Datos!$B$14*B42/365+Datos!$B$18*Escandallo!$D$10)*Datos!$B$11 -> -21593.795
...

Sheet Robot
A1: El robot como decisión independiente del contrato
A2: El caso presenta máquina y contrato como una sola decisión. Separarlos es la clave del análisis: la tecnología es buena aunque el contrato no lo sea.
A4: A. COMPARATIVA TÉCNICA DE LOS TRES SISTEMAS DE FABRICACIÓN
A5: Indicador | B5: Manual | C5: Línea 2019 | D5: Robot nuevo | F5: Lectura
A6: Producción efectiva (palets/día) | B6: =Datos!$B$32 -> 500 | C6: =Datos!$B$21*Datos!$B$22*Datos!$B$8 -> 390 | D6: =Datos!$B$43*Datos!$B$44 -> 360
A7: Operarios necesarios | B7: =Datos!$B$31 -> 8 | C7: =Datos!$B$23 -> 2 | D7: =Datos!$B$45 -> 1
A8: Productividad (palets/operario/día) | B8: =B6/B7 -> 62.5 | C8: =C6/C7 -> 195 | D8: =D6/D7 -> 360 | F8: El robot multiplica por 5,8 la productividad de la fabricación manual.
A9: Cambio de formato (horas) | C9: =Datos!$B$28 -> 6 | D9: =Datos!$B$46/60 -> 0.41666667 | F9: 6 horas de parada frente a menos de media hora: el robot permite series cortas y atender pedidos a medida, que es donde Alcopalet gana margen.
A10: Coste de mano de obra por palet (€) | B10: =Datos!$B$9*B7/(B6*Datos!$B$7) -> 2.5123967 | C10: =Datos!$B$9*C7/(C6*Datos!$B$7) -> 0.80525535 | D10: =Datos!$B$9*D7/(D6*Datos!$B$7) -> 0.43617998 | F10: Coste a plena capacidad de cada sistema. No coincide con el Anexo 3 (2,18 € y 0,42 €) porque el anexo promedia manual y línea automática, y porque atribuye al robot 90.000 unidades cuando su capacidad real es de 87.120.
A12: B. AHORRO TEÓRICO DE MANO DE OBRA
A13: Capacidad anual del robot (palets) | B13: =Capacidad!$B$18 -> 87120
A14: Operarios manuales equivalentes | B14: =B13/(Datos!$B$33*Datos!$B$7) -> 5.76 | F14: Los que harían falta para fabricar lo mismo a mano, a 62,5 palets/operario/día.
A15: Operarios que exige el robot | B15: =Datos!$B$45 -> 1
A16: Operarios liberados | B16: =B14-B15 -> 4.76
A17: AHORRO TEÓRICO BRUTO (€/año) | B17: =B16*Datos!$B$9 -> 180880 | F17: Solo se materializa si esas personas pasan a producir algo vendible.
A18: Cuota anual del leasing, solo la máquina (€) | B18: =-Datos!$B$42*(Datos!$B$11/12)/(1-(1+Datos!$B$11/12)^(-Datos!$B$54*12))*12 -> -9618.2153 | F18: 40.000 € al 7,5% a 5 años. Anualidad calculada, no estimada.
A19: AHORRO TEÓRICO NETO (€/año) | B19: =B17+B18 -> 171261.78
A20: Plazo de recuperación de la inversión (meses) | B20: =Datos!$B$42/B17*12 -> 2.6536931 | F20: Menos de tres meses. Como inversión aislada es excelente.
A22: C. LA RESTRICCIÓN QUE LO CAMBIA TODO: «NO QUIERO DESPIDOS»
A23: Esteban afirma expresamente que no quiere despidos y que el turno único es un valor diferencial para retener a la plantilla. Un ahorro de mano de obra que no se traduce en menos nóminas ni en más producción vendida NO es un ahorro real.
A25: % de mano de obra liberada que se monetiza | B25: =Datos!$B$59 -> 0 | F25: HIPÓTESIS CLAVE, editable en la hoja Datos. 0% = nadie se reasigna ni causa baja.
A26: Ahorro REAL de mano de obra (€/año) | B26: =Robot!$B$17*Datos!$B$59 -> 0
A27: Coste del leasing de la máquina (€/año) | B27: =B18 -> -9618.2153
A28: RESULTADO REAL DEL ROBOT AISLADO (€/año) | B28: =B26+B27 -> -9618.2153 | F28: Con 0% de monetización el robot solo aporta coste. Su valor depende por completo de tener dónde colocar a las personas o el producto.
A29: Vías para monetizar la mano de obra liberada | F29: 1) Reasignar a la línea de palet usado, que necesita +2,6 operarios y solo le falta espacio. 2) Crecer en palet nuevo a precio de mercado. 3) No reponer bajas naturales.
A31: D. COSTE DE OPORTUNIDAD: ¿A QUÉ DEDICAR LA CAPACIDAD DEL ROBOT?
A32: Destino de la producción del robot | B32: Precio (€/ud) | C32: Coste (€/ud) | D32: Margen (€/ud) | E32: Margen anual (€) | F32: Comentario
A33: Fabricar para Persán a 10 € | B33: =Datos!$B$15 -> 10 | C33: =Escandallo!$D$6+Escandallo!$D$7+Escandallo!$D$8+Escandallo!$D$9 -> 10.52 | D33: =B33-C33 -> -0.52 | E33: =D33*Capacidad!$B$18 -> -45302.4 | F33: Precio del contrato tal como está negociado.
A34: Fabricar para el mercado actual a 15,16 € | B34: =Escandallo!$B$5 -> 15.16 | C34: =Escandallo!$D$6+Escandallo!$D$7+Escandallo!$D$8+Escandallo!$D$9 -> 10.52 | D34: =B34-C34 -> 4.64 | E34: =D34*Capacidad!$B$18 -> 404236.8 | F34: Precio medio real del palet nuevo en 2025 (Tetra Pak, Don Simón, Green Box).
A35: Fabricar para Persán renegociado | B35: =Datos!$B$60 -> 12.5 | C35: =Escandallo!$D$6+Escandallo!$D$7+Escandallo!$D$8+Escandallo!$D$9 -> 10.52 | D35: =B35-C35 -> 1.98 | E35: =D35*Capacidad!$B$18 -> 172497.6 | F35: Hipótesis de negociación editable en la hoja Datos.
A36: COSTE DE OPORTUNIDAD (mercado vs Persán) | B36: =E34-E33 -> 449539.2 | F36: Dedicar el robot a Persán en vez de al mercado ordinario cuesta más de 440.000 €/año de margen. La pregunta correcta no es si comprar la máquina, sino a qué dedicarla. Requiere demanda: hoy la fábrica está al 81%.

Sheet Escenarios
A1: Comparación de opciones y proyección del resultado
A2: Cada columna es una de las opciones que el caso pone sobre la mesa. Todos los importes se recalculan desde las hojas anteriores.
A4: Concepto | B4: E0 Statu quo | C4: E1 Persán + robot | D4: E2 Dividendo sin invertir | E4: E3 Robot sin Persán | F4: E4 Robot + Persán renegociado | G4: Comentario
A5: Inversión comprometida (€) | B5: 0 | C5: =Datos!$B$55 -> 190000 | D5: 0 | E5: =Datos!$B$42 -> 40000 | F5: =Datos!$B$55 -> 190000 | G5: E1 y E4 incluyen el tráiler de 150.000 €.
A6: Volumen adicional de palet nuevo (ud) | B6: 0 | C6: =Datos!$B$14 -> 90000 | D6: 0 | E6: 0 | F6: =Datos!$B$14 -> 90000 | G6: E3 no añade volumen: sustituye fabricación manual por robot.
A7: Margen de contribución adicional (€) | B7: 0 | C7: =Persan!$B$7 -> -46800 | D7: 0 | E7: 0 | F7: =(Datos!$B$60-Escandallo!$D$10)*Datos!$B$14 -> 178200
A8: Ahorro real de mano de obra (€) | B8: 0 | C8: 0 | D8: 0 | E8: =Robot!$B$17*Datos!$B$59 -> 0 | F8: 0 | G8: En E1 y E4 el volumen es nuevo: no libera a nadie, exige contratar 1 operario.
A9: Alquiler de la campa (€) | B9: 0 | C9: =-Datos!$B$50 -> -60000 | D9: 0 | E9: 0 | F9: =-Datos!$B$50 -> -60000
A10: Leasing (€) | B10: 0 | C10: =-Datos!$B$53 -> -48000 | D10: 0 | E10: =-Datos!$B$42*(Datos!$B$11/12)/(1-(1+Datos!$B$11/12)^(-Datos!$B$54*12))*12 -> -9618.2153 | F10: =-Datos!$B$53 -> -48000 | G10: En E3 solo se financia la máquina: no hace falta tráiler.
A11: Coste financiero del circulante (€) | B11: 0 | C11: =Persan!$B$16 -> -34076.671 | D11: 0 | E11: 0 | F11: =-(Datos!$B$60*Datos!$B$14*Datos!$B$61/365+Datos!$B$18*Escandallo!$D$10)*Datos!$B$11 -> -21593.795 | G11: E4 supone además reducir el cobro de 180 a 90 días.
A12: IMPACTO ANUAL SOBRE EL RESULTADO (€) | B12: =SUM(B7:B11) -> 0 | C12: =SUM(C7:C11) -> -188876.67 | D12: =SUM(D7:D11) -> 0 | E12: =SUM(E7:E11) -> -9618.2153 | F12: =SUM(F7:F11) -> 48606.205
A13: RESULTADO NETO PROYECTADO (€) | B13: =PyG2025!$B$19+B12 -> 279364 | C13: =PyG2025!$B$19+C12 -> 90487.329 | D13: =PyG2025!$B$19+D12 -> 279364 | E13: =PyG2025!$B$19+E12 -> 269745.78 | F13: =PyG2025!$B$19+F12 -> 327970.21 | G13: Partiendo del resultado neto de 2025 (279.364 €).
A14: Variación sobre el resultado actual | B14: =B12/PyG2025!$B$19 -> 0 | C14: =C12/PyG2025!$B$19 -> -0.67609524 | D14: =D12/PyG2025!$B$19 -> 0 | E14: =E12/PyG2025!$B$19 -> -0.034428972 | F14: =F12/PyG2025!$B$19 -> 0.17398879
A16: IMPACTO EN CAJA DEL PRIMER AÑO
A17: Impacto en resultado (€) | B17: =B12 -> 0 | C17: =C12 -> -188876.67 | D17: =D12 -> 0 | E17: =E12 -> -9618.2153 | F17: =F12 -> 48606.205
A18: (−) Circulante inmovilizado por el cobro aplazado (€) | B18: 0 | C18: =-(Datos!$B$14*Datos!$B$15*Datos!$B$17/365+Datos!$B$18*Escandallo!$D$10) -> -454355.62 | D18: 0 | E18: 0 | F18: =-(Datos!$B$60*Datos!$B$14*Datos!$B$61/365+Datos!$B$18*Escandallo!$D$10) -> -287917.26 | G18: Solo el primer año: después el circulante se mantiene, no se repite.
A19: (−) Dividendo extraordinario (€) | B19: 0 | C19: 0 | D19: =-Datos!$B$63 -> -200000 | E19: 0 | F19: 0 | G19: El caso no cuantifica la casa. Cifra de trabajo editable en la hoja Datos.
A20: NECESIDAD DE CAJA DEL PRIMER AÑO (€) | B20: =SUM(B17:B19) -> 0 | C20: =SUM(C17:C19) -> -643232.29 | D20: =SUM(D17:D19) -> -200000 | E20: =SUM(E17:E19) -> -9618.2153 | F20: =SUM(F17:F19) -> -239311.05 | G20: Contrastar con la caja operativa real de 2025, muy inferior al beneficio contable (ver hoja PyG2025).
A21: Caja operativa generada en 2025 (referencia) | B21: =PyG2025!$B$31 -> -60555
A23: VALORACIÓN CUALITATIVA FRENTE A LOS CRITERIOS DE DECISIÓN
A24: Criterio | B24: E0 | C24: E1 | D24: E2 | E24: E3 | F24: E4 | G24: Observación
A25: Rentabilidad del contrato | B25: n/a | C25: NO | D25: n/a | E25: n/a | F25: SÍ | G25: Solo E4 supera el precio de equilibrio de 12,17 €/ud.
A26: Sostenibilidad de la caja | B26: SÍ | C26: NO | D26: DUDOSA | E26: SÍ | F26: AJUSTADA | G26: E1 exige casi 600.000 € de caja el primer año.
A27: Respeta «sin despidos» | B27: SÍ | C27: SÍ | D27: SÍ | E27: SÍ | F27: SÍ | G27: Ninguna opción obliga a despedir: la capacidad extra se necesita igualmente.
A28: Respeta el turno único | B28: SÍ | C28: SÍ | D28: SÍ | E28: SÍ | F28: SÍ
A29: Permite el plan de crecimiento a 2030 | B29: NO | C29: SÍ | D29: NO | E29: PARCIAL | F29: SÍ | G29: E0 y E2 congelan la empresa en los 3.000 m² actuales.
A30: Da seguridad económica a los fundadores | B30: PARCIAL | C30: NO | D30: SÍ | E30: PARCIAL | F30: PARCIAL | G30: E1 es la que menos margen deja para retribuir a los socios.
A31: Reduce la dependencia de mano de obra | B31: NO | C31: SÍ | D31: NO | E31: SÍ | F31: SÍ | G31: Recurso «cada vez más difícil de gestionar y contratar» según el propio caso.
A32: Riesgo de concentración de cliente | B32: BAJO | C32: ALTO | D32: BAJO | E32: BAJO | F32: MEDIO | G32: Persán supondría el 20% de la facturación con precio fijo a 5 años.

Sheet Sensibilidad
A1: Análisis de sensibilidad del contrato Persán
A2: Impacto anual total (€) según el precio negociado y la evolución del precio de la madera. Incluye campa, leasing y coste del circulante.
A4: Precio de venta negociado (€/ud) → | B4: 10 | C4: 10.5 | D4: 11 | E4: 11.5 | F4: 12 | G4: 12.5 | H4: 13 | I4: 13.5
A5: ↓ Subida del precio de la madera
A6: -0.05 | B6: =Datos!$B$14*(B$4-(Escandallo!$D$6*(1+$A6)+Escandallo!$D$7+Escandallo!$D$8+Escandallo!$D$9))-Datos!$B$50-Datos!$B$53-(B$4*Datos!$B$14*Datos!$B$17/365+Datos!$B$18*Escandallo!$D$10)*Datos!$B$11 -> -151661.67 | C6: =Datos!$B$14*(C$4-(Escandallo!$D$6*(1+$A6)+Escandallo!$D$7+Escandallo!$D$8+Escandallo!$D$9))-Datos!$B$50-Datos!$B$53-(C$4*Datos!$B$14*Datos!$B$17/365+Datos!$B$18*Escandallo!$D$10)*Datos!$B$11 -> -108326.05 | D6: =Datos!$B$14*(D$4-(Escandallo!$D$6*(1+$A6)+Escandallo!$D$7+Escandallo!$D$8+Escandallo!$D$9))-Datos!$B$50-Datos!$B$53-(D$4*Datos!$B$14*Datos!$B$17/365+Datos!$B$18*Escandallo!$D$10)*Datos!$B$11 -> -64990.438 | E6: =Datos!$B$14*(E$4-(Escandallo!$D$6*(1+$A6)+Escandallo!$D$7+Escandallo!$D$8+Escandallo!$D$9))-Datos!$B$50-Datos!$B$53-(E$4*Datos!$B$14*Datos!$B$17/365+Datos!$B$18*Escandallo!$D$10)*Datos!$B$11 -> -21654.822 | F6: =Datos!$B$14*(F$4-(Escandallo!$D$6*(1+$A6)+Escandallo!$D$7+Escandallo!$D$8+Escandallo!$D$9))-Datos!$B$50-Datos!$B$53-(F$4*Datos!$B$14*Datos!$B$17/365+Datos!$B$18*Escandallo!$D$10)*Datos!$B$11 -> 21680.795 | G6: =Datos!$B$14*(G$4-(Escandallo!$D$6*(1+$A6)+Escandallo!$D$7+Escandallo!$D$8+Escandallo!$D$9))-Datos!$B$50-Datos!$B$53-(G$4*Datos!$B$14*Datos!$B$17/365+Datos!$B$18*Escandallo!$D$10)*Datos!$B$11 -> 65016.411 | H6: =Datos!$B$14*(H$4-(Escandallo!$D$6*(1+$A6)+Escandallo!$D$7+Escandallo!$D$8+Escandallo!$D$9))-Datos!$B$50-Datos!$B$53-(H$4*Datos!$B$14*Datos!$B$17/365+Datos!$B$18*Escandallo!$D$10)*Datos!$B$11 -> 108352.03 | I6: =Datos!$B$14*(I$4-(Escandallo!$D$6*(1+$A6)+Escandallo!$D$7+Escandallo!$D$8+Escandallo!$D$9))-Datos!$B$50-Datos!$B$53-(I$4*Datos!$B$14*Datos!$B$17/365+Datos!$B$18*Escandallo!$D$10)*Datos!$B$11 -> 151687.64
A7: 0 | B7: =Datos!$B$14*(B$4-(Escandallo!$D$6*(1+$A7)+Escandallo!$D$7+Escandallo!$D$8+Escandallo!$D$9))-Datos!$B$50-Datos!$B$53-(B$4*Datos!$B$14*Datos!$B$17/365+Datos!$B$18*Escandallo!$D$10)*Datos!$B$11 -> -188876.67 | C7: =Datos!$B$14*(C$4-(Escandallo!$D$6*(1+$A7)+Escandallo!$D$7+Escandallo!$D$8+Escandallo!$D$9))-Datos!$B$50-Datos!$B$53-(C$4*Datos!$B$14*Datos!$B$17/365+Datos!$B$18*Escandallo!$D$10)*Datos!$B$11 -> -145541.05 | D7: =Datos!$B$14*(D$4-(Escandallo!$D$6*(1+$A7)+Escandallo!$D$7+Escandallo!$D$8+Escandallo!$D$9))-Datos!$B$50-Datos!$B$53-(D$4*Datos!$B$14*Datos!$B$17/365+Datos!$B$18*Escandallo!$D$10)*Datos!$B$11 -> -102205.44 | E7: =Datos!$B$14*(E$4-(Escandallo!$D$6*(1+$A7)+Escandallo!$D$7+Escandallo!$D$8+Escandallo!$D$9))-Datos!$B$50-Datos!$B$53-(E$4*Datos!$B$14*Datos!$B$17/365+Datos!$B$18*Escandallo!$D$10)*Datos!$B$11 -> -58869.822 | F7: =Datos!$B$14*(F$4-(Escandallo!$D$6*(1+$A7)+Escandallo!$D$7+Escandallo!$D$8+Escandallo!$D$9))-Datos!$B$50-Datos!$B$53-(F$4*Datos!$B$14*Datos!$B$17/365+Datos!$B$18*Escandallo!$D$10)*Datos!$B$11 -> -15534.205 | G7: =Datos!$B$14*(G$4-(Escandallo!$D$6*(1+$A7)+Escandallo!$D$7+Escandallo!$D$8+Escandallo!$D$9))-Datos!$B$50-Datos!$B$53-(G$4*Datos!$B$14*Datos!$B$17/365+Datos!$B$18*Escandallo!$D$10)*Datos!$B$11 -> 27801.411 | H7: =Datos!$B$14*(H$4-(Escandallo!$D$6*(1+$A7)+Escandallo!$D$7+Escandallo!$D$8+Escandallo!$D$9))-Datos!$B$50-Datos!$B$53-(H$4*Datos!$B$14*Datos!$B$17/365+Datos!$B$18*Escandallo!$D$10)*Datos!$B$11 -> 71137.027 | I7: =Datos!$B$14*(I$4-(Escandallo!$D$6*(1+$A7)+Escandallo!$D$7+Escandallo!$D$8+Escandallo!$D$9))-Datos!$B$50-Datos!$B$53-(I$4*Datos!$B$14*Datos!$B$17/365+Datos!$B$18*Escandallo!$D$10)*Datos!$B$11 -> 114472.64
A8: 0.05 | B8: =Datos!$B$14*(B$4-(Escandallo!$D$6*(1+$A8)+Escandallo!$D$7+Escandallo!$D$8+Escandallo!$D$9))-Datos!$B$50-Datos!$B$53-(B$4*Datos!$B$14*Datos!$B$17/365+Datos!$B$18*Escandallo!$D$10)*Datos!$B$11 -> -226091.67 | C8: =Datos!$B$14*(C$4-(Escandallo!$D$6*(1+$A8)+Escandallo!$D$7+Escandallo!$D$8+Escandallo!$D$9))-Datos!$B$50-Datos!$B$53-(C$4*Datos!$B$14*Datos!$B$17/365+Datos!$B$18*Escandallo!$D$10)*Datos!$B$11 -> -182756.05 | D8: =Datos!$B$14*(D$4-(Escandallo!$D$6*(1+$A8)+Escandallo!$D$7+Escandallo!$D$8+Escandallo!$D$9))-Datos!$B$50-Datos!$B$53-(D$4*Datos!$B$14*Datos!$B$17/365+Datos!$B$18*Escandallo!$D$10)*Datos!$B$11 -> -139420.44 | E8: =Datos!$B$14*(E$4-(Escandallo!$D$6*(1+$A8)+Escandallo!$D$7+Escandallo!$D$8+Escandallo!$D$9))-Datos!$B$50-Datos!$B$53-(E$4*Datos!$B$14*Datos!$B$17/365+Datos!$B$18*Escandallo!$D$10)*Datos!$B$11 -> -96084.822 | F8: =Datos!$B$14*(F$4-(Escandallo!$D$6*(1+$A8)+Escandallo!$D$7+Escandallo!$D$8+Escandallo!$D$9))-Datos!$B$50-Datos!$B$53-(F$4*Datos!$B$14*Datos!$B$17/365+Datos!$B$18*Escandallo!$D$10)*Datos!$B$11 -> -52749.205 | G8: =Datos!$B$14*(G$4-(Escandallo!$D$6*(1+$A8)+Escandallo!$D$7+Escandallo!$D$8+Escandallo!$D$9))-Datos!$B$50-Datos!$B$53-(G$4*Datos!$B$14*Datos!$B$17/365+Datos!$B$18*Escandallo!$D$10)*Datos!$B$11 -> -9413.589 | H8: =Datos!$B$14*(H$4-(Escandallo!$D$6*(1+$A8)+Escandallo!$D$7+Escandallo!$D$8+Escandallo!$D$9))-Datos!$B$50-Datos!$B$53-(H$4*Datos!$B$14*Datos!$B$17/365+Datos!$B$18*Escandallo!$D$10)*Datos!$B$11 -> 33922.027 | I8: =Datos!$B$14*(I$4-(Escandallo!$D$6*(1+$A8)+Escandallo!$D$7+Escandallo!$D$8+Escandallo!$D$9))-Datos!$B$50-Datos!$B$53-(I$4*Datos!$B$14*Datos!$B$17/365+Datos!$B$18*Escandallo!$D$10)*Datos!$B$11 -> 77257.644
A9: 0.1 | B9: =Datos!$B$14*(B$4-(Escandallo!$D$6*(1+$A9)+Escandallo!$D$7+Escandallo!$D$8+Escandallo!$D$9))-Datos!$B$50-Datos!$B$53-(B$4*Datos!$B$14*Datos!$B$17/365+Datos!$B$18*Escandallo!$D$10)*Datos!$B$11 -> -263306.67 | C9: =Datos!$B$14*(C$4-(Escandallo!$D$6*(1+$A9)+Escandallo!$D$7+Escandallo!$D$8+Escandallo!$D$9))-Datos!$B$50-Datos!$B$53-(C$4*Datos!$B$14*Datos!$B$17/365+Datos!$B$18*Escandallo!$D$10)*Datos!$B$11 -> -219971.05 | D9: =Datos!$B$14*(D$4-(Escandallo!$D$6*(1+$A9)+Escandallo!$D$7+Escandallo!$D$8+Escandallo!$D$9))-Datos!$B$50-Datos!$B$53-(D$4*Datos!$B$14*Datos!$B$17/365+Datos!$B$18*Escandallo!$D$10)*Datos!$B$11 -> -176635.44 | E9: =Datos!$B$14*(E$4-(Escandallo!$D$6*(1+$A9)+Escandallo!$D$7+Escandallo!$D$8+Escandallo!$D$9))-Datos!$B$50-Datos!$B$53-(E$4*Datos!$B$14*Datos!$B$17/365+Datos!$B$18*Escandallo!$D$10)*Datos!$B$11 -> -133299.82 | F9: =Datos!$B$14*(F$4-(Escandallo!$D$6*(1+$A9)+Escandallo!$D$7+Escandallo!$D$8+Escandallo!$D$9))-Datos!$B$50-Datos!$B$53-(F$4*Datos!$B$14*Datos!$B$17/365+Datos!$B$18*Escandallo!$D$10)*Datos!$B$11 -> -89964.205 | G9: =Datos!$B$14*(G$4-(Escandallo!$D$6*(1+$A9)+Escandallo!$D$7+Escandallo!$D$8+Escandallo!$D$9))-Datos!$B$50-Datos!$B$53-(G$4*Datos!$B$14*Datos!$B$17/365+Datos!$B$18*Escandallo!$D$10)*Datos!$B$11 -> -46628.589 | H9: =Datos!$B$14*(H$4-(Escandallo!$D$6*(1+$A9)+Escandallo!$D$7+Escandallo!$D$8+Escandallo!$D$9))-Datos!$B$50-Datos!$B$53-(H$4*Datos!$B$14*Datos!$B$17/365+Datos!$B$18*Escandallo!$D$10)*Datos!$B$11 -> -3292.9726 | I9: =Datos!$B$14*(I$4-(Escandallo!$D$6*(1+$A9)+Escandallo!$D$7+Escandallo!$D$8+Escandallo!$D$9))-Datos!$B$50-Datos!$B$53-(I$4*Datos!$B$14*Datos!$B$17/365+Datos!$B$18*Escandallo!$D$10)*Datos!$B$11 -> 40042.644
A10: 0.15 | B10: =Datos!$B$14*(B$4-(Escandallo!$D$6*(1+$A10)+Escandallo!$D$7+Escandallo!$D$8+Escandallo!$D$9))-Datos!$B$50-Datos!$B$53-(B$4*Datos!$B$14*Datos!$B$17/365+Datos!$B$18*Escandallo!$D$10)*Datos!$B$11 -> -300521.67 | C10: =Datos!$B$14*(C$4-(Escandallo!$D$6*(1+$A10)+Escandallo!$D$7+Escandallo!$D$8+Escandallo!$D$9))-Datos!$B$50-Datos!$B$53-(C$4*Datos!$B$14*Datos!$B$17/365+Datos!$B$18*Escandallo!$D$10)*Datos!$B$11 -> -257186.05 | D10: =Datos!$B$14*(D$4-(Escandallo!$D$6*(1+$A10)+Escandallo!$D$7+Escandallo!$D$8+Escandallo!$D$9))-Datos!$B$50-Datos!$B$53-(D$4*Datos!$B$14*Datos!$B$17/365+Datos!$B$18*Escandallo!$D$10)*Datos!$B$11 -> -213850.44 | E10: =Datos!$B$14*(E$4-(Escandallo!$D$6*(1+$A10)+Escandallo!$D$7+Escandallo!$D$8+Escandallo!$D$9))-Datos!$B$50-Datos!$B$53-(E$4*Datos!$B$14*Datos!$B$17/365+Datos!$B$18*Escandallo!$D$10)*Datos!$B$11 -> -170514.82 | F10: =Datos!$B$14*(F$4-(Escandallo!$D$6*(1+$A10)+Escandallo!$D$7+Escandallo!$D$8+Escandallo!$D$9))-Datos!$B$50-Datos!$B$53-(F$4*Datos!$B$14*Datos!$B$17/365+Datos!$B$18*Escandallo!$D$10)*Datos!$B$11 -> -127179.21 | G10: =Datos!$B$14*(G$4-(Escandallo!$D$6*(1+$A10)+Escandallo!$D$7+Escandallo!$D$8+Escandallo!$D$9))-Datos!$B$50-Datos!$B$53-(G$4*Datos!$B$14*Datos!$B$17/365+Datos!$B$18*Escandallo!$D$10)*Datos!$B$11 -> -83843.589 | H10: =Datos!$B$14*(H$4-(Escandallo!$D$6*(1+$A10)+Escandallo!$D$7+Escandallo!$D$8+Escandallo!$D$9))-Datos!$B$50-Datos!$B$53-(H$4*Datos!$B$14*Datos!$B$17/365+Datos!$B$18*Escandallo!$D$10)*Datos!$B$11 -> -40507.973 | I10: =Datos!$B$14*(I$4-(Escandallo!$D$6*(1+$A10)+Escandallo!$D$7+Escandallo!$D$8+Escandallo!$D$9))-Datos!$B$50-Datos!$B$53-(I$4*Datos!$B$14*Datos!$B$17/365+Datos!$B$18*Escandallo!$D$10)*Datos!$B$11 -> 2827.6438
A11: 0.2 | B11: =Datos!$B$14*(B$4-(Escandallo!$D$6*(1+$A11)+Escandallo!$D$7+Escandallo!$D$8+Escandallo!$D$9))-Datos!$B$50-Datos!$B$53-(B$4*Datos!$B$14*Datos!$B$17/365+Datos!$B$18*Escandallo!$D$10)*Datos!$B$11 -> -337736.67 | C11: =Datos!$B$14*(C$4-(Escandallo!$D$6*(1+$A11)+Escandallo!$D$7+Escandallo!$D$8+Escandallo!$D$9))-Datos!$B$50-Datos!$B$53-(C$4*Datos!$B$14*Datos!$B$17/365+Datos!$B$18*Escandallo!$D$10)*Datos!$B$11 -> -294401.05 | D11: =Datos!$B$14*(D$4-(Escandallo!$D$6*(1+$A11)+Escandallo!$D$7+Escandallo!$D$8+Escandallo!$D$9))-Datos!$B$50-Datos!$B$53-(D$4*Datos!$B$14*Datos!$B$17/365+Datos!$B$18*Escandallo!$D$10)*Datos!$B$11 -> -251065.44 | E11: =Datos!$B$14*(E$4-(Escandallo!$D$6*(1+$A11)+Escandallo!$D$7+Escandallo!$D$8+Escandallo!$D$9))-Datos!$B$50-Datos!$B$53-(E$4*Datos!$B$14*Datos!$B$17/365+Datos!$B$18*Escandallo!$D$10)*Datos!$B$11 -> -207729.82 | F11: =Datos!$B$14*(F$4-(Escandallo!$D$6*(1+$A11)+Escandallo!$D$7+Escandallo!$D$8+Escandallo!$D$9))-Datos!$B$50-Datos!$B$53-(F$4*Datos!$B$14*Datos!$B$17/365+Datos!$B$18*Escandallo!$D$10)*Datos!$B$11 -> -164394.21 | G11: =Datos!$B$14*(G$4-(Escandallo!$D$6*(1+$A11)+Escandallo!$D$7+Escandallo!$D$8+Escandallo!$D$9))-Datos!$B$50-Datos!$B$53-(G$4*Datos!$B$14*Datos!$B$17/365+Datos!$B$18*Escandallo!$D$10)*Datos!$B$11 -> -121058.59 | H11: =Datos!$B$14*(H$4-(Escandallo!$D$6*(1+$A11)+Escandallo!$D$7+Escandallo!$D$8+Escandallo!$D$9))-Datos!$B$50-Datos!$B$53-(H$4*Datos!$B$14*Datos!$B$17/365+Datos!$B$18*Escandallo!$D$10)*Datos!$B$11 -> -77722.973 | I11: =Datos!$B$14*(I$4-(Escandallo!$D$6*(1+$A11)+Escandallo!$D$7+Escandallo!$D$8+Escandallo!$D$9))-Datos!$B$50-Datos!$B$53-(I$4*Datos!$B$14*Datos!$B$17/365+Datos!$B$18*Escandallo!$D$10)*Datos!$B$11 -> -34387.356
A13: Lectura: la zona en negativo es la combinación en la que el contrato destruye valor. Con el precio actual de 10 € el contrato pierde dinero incluso si la madera BAJA un 5%.
A14: El punto de equilibrio con madera estable está en torno a 12,17 €/ud: por debajo de ese precio, ningún volumen ni ninguna máquina arreglan el contrato.
A17: SENSIBILIDAD AL PLAZO DE COBRO (precio fijo de 10 €/ud)
A18: Plazo de cobro (días) | B18: Circulante inmovilizado (€) | C18: Coste financiero anual (€) | D18: Impacto total (€) | F18: Lectura
A19: 30 | B19: =Datos!$B$14*Datos!$B$15*A19/365+Datos!$B$18*Escandallo!$D$10 -> 84492.603 | C19: =-B19*Datos!$B$11 -> -6336.9452 | D19: =Persan!$B$7-Datos!$B$50-Datos!$B$53+C19 -> -161136.95
A20: 60 | B20: =Datos!$B$14*Datos!$B$15*A20/365+Datos!$B$18*Escandallo!$D$10 -> 158465.21 | C20: =-B20*Datos!$B$11 -> -11884.89 | D20: =Persan!$B$7-Datos!$B$50-Datos!$B$53+C20 -> -166684.89
A21: 90 | B21: =Datos!$B$14*Datos!$B$15*A21/365+Datos!$B$18*Escandallo!$D$10 -> 232437.81 | C21: =-B21*Datos!$B$11 -> -17432.836 | D21: =Persan!$B$7-Datos!$B$50-Datos!$B$53+C21 -> -172232.84
A22: 120 | B22: =Datos!$B$14*Datos!$B$15*A22/365+Datos!$B$18*Escandallo!$D$10 -> 306410.41 | C22: =-B22*Datos!$B$11 -> -22980.781 | D22: =Persan!$B$7-Datos!$B$50-Datos!$B$53+C22 -> -177780.78
A23: 180 | B23: =Datos!$B$14*Datos!$B$15*A23/365+Datos!$B$18*Escandallo!$D$10 -> 454355.62 | C23: =-B23*Datos!$B$11 -> -34076.671 | D23: =Persan!$B$7-Datos!$B$50-Datos!$B$53+C23 -> -188876.67
A24: Negociar el plazo de cobro ayuda, pero no salva el contrato: el problema de fondo es el precio, no el aplazamiento.
